<?xml version="1.0"?>
<robot xmlns:xacro="http://www.ros.org/wiki/xacro" name= "lidarbot">

    <xacro:include filename="inertial_macros.xacro" />

    <xacro:property name="pi" value="3.141592653589793" />


    <material name = "white">
        <color rgba="1 1 1 1"/>
    </material>

    <material name="grey">
        <color rgba="0.7 0.7 0.7 1"/>
    </material>

    <material name="green">
        <color rgba="0 0.6 0 1"/>
    </material>

    <!--Base link-->

    <link name="base_link">

    </link>

    <!-- Base footprint link-->

    <link name= "base_footprint">
    </link>

    <joint name="base_footprint_joint" type="fixed">
        <parent link="base_link"/>
        <child link="base_footprint"/>
        <origin xyz="0.0 0.0 0.0" rpy="0.0 0.0 0.0"/>
    </joint>

    <!--Chassis-->

    <joint name="chassis_joint" type="fixed">
        <parent link="base_link"/>
        <child link="chassis"/>
        <origin xyz="0.0 0.0 0.0" rpy="0.0 0.0 0.0"/> #0.0 0.0 0.1
    </joint>

    <link name="chassis">
        <visual>
            <geometry>
                <box size="0.6 0.4 0.2"/>
            </geometry>
            <origin xyz="0 0 0.1" rpy="0 0 0"/>
            <material name="green"/> 
        </visual>
        <collision>
            <geometry>
                <box size="0.6 0.4 0.2"/>
            </geometry>
            <origin xyz="0 0 0.1" rpy="0 0 0"/>
        </collision>
        <xacro:inertial_box mass= "0.5" x = "0.6" y = "0.4" z = "0.2">
            <origin xyz = "0 0 0.1" rpy="0 0 0"/>
        </xacro:inertial_box>
    </link>

    <gazebo reference= "chassis">
        <material>Gazebo/White</material>
    </gazebo>

    <!-- Left wheel -->

    <joint name="left_wheel_joint" type="continuous">
        <parent link="base_link"/>
        <child link="left_wheel"/>
        <origin xyz="-0.15 0.225 0.0" rpy="0.0 0.0 0.0"/> #-0.15 0.225 0.0
        <axis xyz="0.0 1.0 0.0"/>
    </joint>

    <link name="left_wheel">
        <visual>
            <geometry>
                <cylinder radius="0.1" length="0.05"/>
            </geometry>
            <origin xyz="0.0 0.0 0.0" rpy="1.57 0.0 0.0"/>
            <material name="grey"/>
        </visual>
        <collision>
            <geometry>
                <cylinder radius="0.1" length="0.05"/>
            </geometry>
            <origin xyz="0.0 0.0 0.0" rpy="1.57 0.0 0.0"/>
        </collision>
        <xacro:inertial_cylinder mass="0.1" length= "0.05" radius="0.1">
            <origin xyz="0.0 0.0 0.0" rpy="1.57 0.0 0.0"/>
        </xacro:inertial_cylinder>
    </link>

    <gazebo reference= "left_wheel">
        <material>Gazebo/Black</material>
    </gazebo>

    <!--Right wheel-->

    <joint name="right_wheel_joint" type="continuous">
        <parent link="base_link"/>
        <child link="right_wheel"/>
        <origin xyz="-0.15 -0.225 0.0" rpy="0.0 0.0 0.0"/>
        <axis xyz="0.0 1.0 0.0"/>
    </joint>

    <link name="right_wheel">
        <visual>
            <geometry>
                <cylinder radius="0.1" length="0.05"/>
            </geometry>
            <origin xyz="0.0 0.0 0.0" rpy="1.57 0.0 0.0"/>
            <material name="grey"/>
        </visual>
        <collision>
            <geometry>
                <cylinder radius="0.1" length="0.05"/>
            </geometry>
            <origin xyz="0.0 0.0 0.0" rpy="1.57 0.0 0.0"/>
        </collision>
        <xacro:inertial_cylinder mass="0.1" length= "0.05" radius="0.1">
            <origin xyz="0.0 0.0 0.0" rpy="1.57 0.0 0.0"/>
        </xacro:inertial_cylinder>
    </link>

    <gazebo reference= "right_wheel">
        <material>Gazebo/Black</material>
    </gazebo>



    <!--Caster wheel-->

    <joint name="base_caster_wheel" type="fixed">
        <parent link="base_link"/>
        <child link="caster_wheel"/>
        <origin xyz="0.20 0.0 -0.05" rpy="0.0 0.0 0.0"/>
        <axis xyz="0.0 0.0 0.0"/>
    </joint>

    <link name="caster_wheel">
        <visual>
            <geometry>
                <sphere radius="0.05"/>
            </geometry>
            <origin xyz="0.0 0.0 0.0" rpy="0.0 0.0 0.0"/>
            <material name="grey"/>
        </visual>
        <collision>
            <geometry>
                <sphere radius="0.05"/>
            </geometry>
            <origin xyz="0.0 0.0 0.0" rpy="0.0 0.0 0.0"/>
        </collision>
        <xacro:inertial_sphere mass="0.1" radius="0.05">
            <origin xyz="0.0 0.0 0.0" rpy="0.0 0.0 0.0"/>
        </xacro:inertial_sphere>
    </link>

    <gazebo reference= "caster_wheel">
        <material>Gazebo/Blue</material>
        <mu1 value="0.001"/>
        <mu2 value="0.001"/>
    </gazebo>


</robot>
            